2025-03-17 22:29:56,252 INFO    Thread-15 (_run_job):19288 [wandb_setup.py:_flush():67] Current SDK version is 0.19.8
2025-03-17 22:29:56,252 INFO    Thread-15 (_run_job):19288 [wandb_setup.py:_flush():67] Configure stats pid to 19288
2025-03-17 22:29:56,253 INFO    Thread-15 (_run_job):19288 [wandb_setup.py:_flush():67] Loading settings from C:\Users\praha\.config\wandb\settings
2025-03-17 22:29:56,253 INFO    Thread-15 (_run_job):19288 [wandb_setup.py:_flush():67] Loading settings from C:\Users\praha\Documents\IIT madras\Acads\sem 10\introtoDL\DA6401_A01\wandb\settings
2025-03-17 22:29:56,253 INFO    Thread-15 (_run_job):19288 [wandb_setup.py:_flush():67] Loading settings from environment variables
2025-03-17 22:29:56,253 INFO    Thread-15 (_run_job):19288 [wandb_init.py:setup_run_log_directory():647] Logging user logs to C:\Users\praha\Documents\IIT madras\Acads\sem 10\introtoDL\DA6401_A01\wandb\run-20250317_222956-01397gpl\logs\debug.log
2025-03-17 22:29:56,254 INFO    Thread-15 (_run_job):19288 [wandb_init.py:setup_run_log_directory():648] Logging internal logs to C:\Users\praha\Documents\IIT madras\Acads\sem 10\introtoDL\DA6401_A01\wandb\run-20250317_222956-01397gpl\logs\debug-internal.log
2025-03-17 22:29:56,254 INFO    Thread-15 (_run_job):19288 [wandb_init.py:init():761] calling init triggers
2025-03-17 22:29:56,254 INFO    Thread-15 (_run_job):19288 [wandb_init.py:init():766] wandb.init called with sweep_config: {'activation': 'tanh', 'batch_size': 16, 'beta': 0.9, 'beta1': 0.9, 'beta2': 0.999, 'epochs': 5, 'epsilon': 1e-08, 'hidden_size': 32, 'learning_rate': 0.0001, 'loss': 'cross_entropy', 'momentum': 0.9, 'num_layers': 5, 'optimizer': 'sgd', 'weight_decay': 0, 'weight_init': 'Xavier'}
config: {'_wandb': {}}
2025-03-17 22:29:56,255 INFO    Thread-15 (_run_job):19288 [wandb_init.py:init():784] starting backend
2025-03-17 22:29:56,255 INFO    Thread-15 (_run_job):19288 [wandb_init.py:init():788] sending inform_init request
2025-03-17 22:29:56,286 INFO    Thread-15 (_run_job):19288 [backend.py:_multiprocessing_setup():101] multiprocessing start_methods=spawn, using: spawn
2025-03-17 22:29:56,286 INFO    Thread-15 (_run_job):19288 [wandb_init.py:init():798] backend started and connected
2025-03-17 22:29:56,289 INFO    Thread-15 (_run_job):19288 [wandb_run.py:_config_callback():1261] config_cb None None {'activation': 'tanh', 'batch_size': 16, 'beta': 0.9, 'beta1': 0.9, 'beta2': 0.999, 'epochs': 5, 'epsilon': 1e-08, 'hidden_size': 32, 'learning_rate': 0.0001, 'loss': 'cross_entropy', 'momentum': 0.9, 'num_layers': 5, 'optimizer': 'sgd', 'weight_decay': 0, 'weight_init': 'Xavier'}
2025-03-17 22:29:56,290 INFO    Thread-15 (_run_job):19288 [wandb_init.py:init():891] updated telemetry
2025-03-17 22:29:56,353 INFO    Thread-15 (_run_job):19288 [wandb_init.py:init():915] communicating run to backend with 90.0 second timeout
2025-03-17 22:29:56,783 INFO    Thread-15 (_run_job):19288 [wandb_init.py:init():990] starting run threads in backend
2025-03-17 22:29:57,616 INFO    Thread-15 (_run_job):19288 [wandb_run.py:_console_start():2375] atexit reg
2025-03-17 22:29:57,618 INFO    Thread-15 (_run_job):19288 [wandb_run.py:_redirect():2227] redirect: wrap_raw
2025-03-17 22:29:57,618 INFO    Thread-15 (_run_job):19288 [wandb_run.py:_redirect():2292] Wrapping output streams.
2025-03-17 22:29:57,619 INFO    Thread-15 (_run_job):19288 [wandb_run.py:_redirect():2315] Redirects installed.
2025-03-17 22:29:57,631 INFO    Thread-15 (_run_job):19288 [wandb_init.py:init():1032] run started, returning control to user process
2025-03-17 22:30:21,366 INFO    Thread-15 (_run_job):19288 [wandb_run.py:_finish():2112] finishing run prahaladvathsan-iit-madras/DA640_A01/01397gpl
2025-03-17 22:30:21,367 INFO    Thread-15 (_run_job):19288 [wandb_run.py:_atexit_cleanup():2340] got exitcode: 0
2025-03-17 22:30:21,368 INFO    Thread-15 (_run_job):19288 [wandb_run.py:_restore():2322] restore
2025-03-17 22:30:21,368 INFO    Thread-15 (_run_job):19288 [wandb_run.py:_restore():2328] restore done
2025-03-17 22:30:53,611 INFO    Thread-19 (wrapped_target):19288 [retry.py:__call__():175] Retry attempt failed:
Traceback (most recent call last):
  File "c:\Users\praha\miniconda3\envs\DS\lib\site-packages\urllib3\connection.py", line 203, in _new_conn
    sock = connection.create_connection(
  File "c:\Users\praha\miniconda3\envs\DS\lib\site-packages\urllib3\util\connection.py", line 85, in create_connection
    raise err
  File "c:\Users\praha\miniconda3\envs\DS\lib\site-packages\urllib3\util\connection.py", line 73, in create_connection
    sock.connect(sa)
TimeoutError: timed out

The above exception was the direct cause of the following exception:

Traceback (most recent call last):
  File "c:\Users\praha\miniconda3\envs\DS\lib\site-packages\urllib3\connectionpool.py", line 790, in urlopen
    response = self._make_request(
  File "c:\Users\praha\miniconda3\envs\DS\lib\site-packages\urllib3\connectionpool.py", line 491, in _make_request
    raise new_e
  File "c:\Users\praha\miniconda3\envs\DS\lib\site-packages\urllib3\connectionpool.py", line 467, in _make_request
    self._validate_conn(conn)
  File "c:\Users\praha\miniconda3\envs\DS\lib\site-packages\urllib3\connectionpool.py", line 1096, in _validate_conn
    conn.connect()
  File "c:\Users\praha\miniconda3\envs\DS\lib\site-packages\urllib3\connection.py", line 611, in connect
    self.sock = sock = self._new_conn()
  File "c:\Users\praha\miniconda3\envs\DS\lib\site-packages\urllib3\connection.py", line 212, in _new_conn
    raise ConnectTimeoutError(
urllib3.exceptions.ConnectTimeoutError: (<urllib3.connection.HTTPSConnection object at 0x0000018D9A6957E0>, 'Connection to api.wandb.ai timed out. (connect timeout=20)')

The above exception was the direct cause of the following exception:

Traceback (most recent call last):
  File "c:\Users\praha\miniconda3\envs\DS\lib\site-packages\requests\adapters.py", line 486, in send
    resp = conn.urlopen(
  File "c:\Users\praha\miniconda3\envs\DS\lib\site-packages\urllib3\connectionpool.py", line 844, in urlopen
    retries = retries.increment(
  File "c:\Users\praha\miniconda3\envs\DS\lib\site-packages\urllib3\util\retry.py", line 515, in increment
    raise MaxRetryError(_pool, url, reason) from reason  # type: ignore[arg-type]
urllib3.exceptions.MaxRetryError: HTTPSConnectionPool(host='api.wandb.ai', port=443): Max retries exceeded with url: /graphql (Caused by ConnectTimeoutError(<urllib3.connection.HTTPSConnection object at 0x0000018D9A6957E0>, 'Connection to api.wandb.ai timed out. (connect timeout=20)'))

During handling of the above exception, another exception occurred:

Traceback (most recent call last):
  File "c:\Users\praha\miniconda3\envs\DS\lib\site-packages\wandb\sdk\lib\retry.py", line 134, in __call__
    result = self._call_fn(*args, **kwargs)
  File "c:\Users\praha\miniconda3\envs\DS\lib\site-packages\wandb\sdk\internal\internal_api.py", line 398, in execute
    return self.client.execute(*args, **kwargs)  # type: ignore
  File "c:\Users\praha\miniconda3\envs\DS\lib\site-packages\wandb\vendor\gql-0.2.0\wandb_gql\client.py", line 52, in execute
    result = self._get_result(document, *args, **kwargs)
  File "c:\Users\praha\miniconda3\envs\DS\lib\site-packages\wandb\vendor\gql-0.2.0\wandb_gql\client.py", line 60, in _get_result
    return self.transport.execute(document, *args, **kwargs)
  File "c:\Users\praha\miniconda3\envs\DS\lib\site-packages\wandb\sdk\lib\gql_request.py", line 58, in execute
    request = self.session.post(self.url, **post_args)
  File "c:\Users\praha\miniconda3\envs\DS\lib\site-packages\requests\sessions.py", line 637, in post
    return self.request("POST", url, data=data, json=json, **kwargs)
  File "c:\Users\praha\miniconda3\envs\DS\lib\site-packages\requests\sessions.py", line 589, in request
    resp = self.send(prep, **send_kwargs)
  File "c:\Users\praha\miniconda3\envs\DS\lib\site-packages\requests\sessions.py", line 703, in send
    r = adapter.send(request, **kwargs)
  File "c:\Users\praha\miniconda3\envs\DS\lib\site-packages\requests\adapters.py", line 507, in send
    raise ConnectTimeout(e, request=request)
requests.exceptions.ConnectTimeout: HTTPSConnectionPool(host='api.wandb.ai', port=443): Max retries exceeded with url: /graphql (Caused by ConnectTimeoutError(<urllib3.connection.HTTPSConnection object at 0x0000018D9A6957E0>, 'Connection to api.wandb.ai timed out. (connect timeout=20)'))
2025-03-17 22:31:00,048 INFO    Thread-15 (_run_job):19288 [wandb_run.py:_footer_history_summary_info():3956] rendering history
2025-03-17 22:31:00,049 INFO    Thread-15 (_run_job):19288 [wandb_run.py:_footer_history_summary_info():3988] rendering summary
2025-03-17 22:31:00,051 INFO    Thread-15 (_run_job):19288 [wandb_run.py:_footer_sync_info():3917] logging synced files
